Defaulting to user installation because normal site-packages is not writeable
Requirement already satisfied: discord.py in ./.local/lib/python3.9/site-packages (1.7.3)
Requirement already satisfied: aiohttp<3.8.0,>=3.6.0 in ./.local/lib/python3.9/site-packages (from discord.py) (3.7.4.post0)
Requirement already satisfied: chardet<5.0,>=2.0 in ./.local/lib/python3.9/site-packages (from aiohttp<3.8.0,>=3.6.0->discord.py) (4.0.0)
Requirement already satisfied: yarl<2.0,>=1.0 in ./.local/lib/python3.9/site-packages (from aiohttp<3.8.0,>=3.6.0->discord.py) (1.6.3)
Requirement already satisfied: attrs>=17.3.0 in ./.local/lib/python3.9/site-packages (from aiohttp<3.8.0,>=3.6.0->discord.py) (21.2.0)
Requirement already satisfied: multidict<7.0,>=4.5 in ./.local/lib/python3.9/site-packages (from aiohttp<3.8.0,>=3.6.0->discord.py) (5.2.0)
Requirement already satisfied: typing-extensions>=3.6.5 in ./.local/lib/python3.9/site-packages (from aiohttp<3.8.0,>=3.6.0->discord.py) (3.10.0.2)
Requirement already satisfied: async-timeout<4.0,>=3.0 in ./.local/lib/python3.9/site-packages (from aiohttp<3.8.0,>=3.6.0->discord.py) (3.0.1)
Requirement already satisfied: idna>=2.0 in /usr/lib/python3/dist-packages (from yarl<2.0,>=1.0->aiohttp<3.8.0,>=3.6.0->discord.py) (2.6)
WARNING: You are using pip version 21.2.4; however, version 21.3 is available.
You should consider upgrading via the '/usr/bin/python3.7 -m pip install --upgrade pip' command.
Logged in as altereal.bot (ID: 4WP0JYEd)
------
server has 84 channels.
'<ChannelType.chat> Comment √©crire'
'<ChannelType.chat> üåê Darknet'
'<ChannelType.chat> Empathie'
'<ChannelType.chat> Athl√©tisme'
'<ChannelType.chat> Entropie'
'<ChannelType.chat> Conseil des traditions'
'<ChannelType.docs> R√®gles'
'<ChannelType.chat> Mentor'
'<ChannelType.chat> Influence'
'<ChannelType.chat> Vie'
'<ChannelType.chat> Statut'
'<ChannelType.chat> Alli√©s'
'<ChannelType.forum> forum'
'<ChannelType.chat> Technologie'
'<ChannelType.chat> Bagarre'
'<ChannelType.chat> Raison'
'<ChannelType.chat> Occultisme'
'<ChannelType.chat> Dext√©rit√©'
'<ChannelType.forum> Nom du Personnage - Suivi'
'<ChannelType.chat> Esprits'
'<ChannelType.chat> Investigation'
'<ChannelType.chat> Fausse identit√©'
'<ChannelType.chat> M√™l√©e'
'<ChannelType.chat> Forces'
'<ChannelType.chat> M√©decine'
'<ChannelType.chat> Prime'
'<ChannelType.chat> Ressources'
'<ChannelType.chat> Familier'
'<ChannelType.chat> üåê Internet'
'<ChannelType.chat> tests de bot'
'<ChannelType.chat> Informatique'
'<ChannelType.forum> Questions de r√®gles'
'<ChannelType.chat> Art'
'<ChannelType.chat> Sondages'
'<ChannelType.chat> G√©n√©ral (hors jeu)'
'<ChannelType.chat> √âsot√©risme'
'<ChannelType.chat> Renomm√©e'
'<ChannelType.chat> Vigilance'
'<ChannelType.chat> Artisanats'
'<ChannelType.chat> Etiquette'
'<ChannelType.chat> Parrain'
'<ChannelType.chat> Survie'
'<ChannelType.chat> Manipulation'
'<ChannelType.chat> Expression'
'<ChannelType.chat> Perception'
'<ChannelType.chat> Id√©es vrac from IRL'
'<ChannelType.chat> Sillicon Valley - Narration'
'<ChannelType.chat> M√©ditation'
'<ChannelType.chat> Yosemite - Narration'
'<ChannelType.chat> Mati√®re'
'<ChannelType.chat> Subterfuge'
'<ChannelType.chat> Commandement'
'<ChannelType.chat> Alcatraz - Narration'
'<ChannelType.chat> Sciences'
'<ChannelType.chat> Empathie'
'<ChannelType.chat> Charte'
Help on method history in module guilded.abc:

async history(*, limit: int = 50) -> List[guilded.message.ChatMessage] method of guilded.channel.ChatChannel instance
    |coro|
    
    Fetch the message history of this channel.
    
    Parameters
    -----------
    limit: Optional[:class:`int`]
        The maximum number of messages to fetch. Defaults to 50.
    
    Returns
    --------
    List[:class:`Message`]

None
Ignoring exception in command backupChannel:
Traceback (most recent call last):
  File "/home/minecraft/multicraft/servers/server223117/.local/lib/python3.9/site-packages/guilded/ext/commands/core.py", line 83, in wrapped
    ret = await coro(*args, **kwargs)
  File "/home/minecraft/multicraft/servers/server223117/guilded_altereal.py", line 148, in backupChannel
    messageList = await channel.history()
  File "/home/minecraft/multicraft/servers/server223117/.local/lib/python3.9/site-packages/guilded/abc.py", line 233, in history
    history = await self._state.get_channel_messages(self._channel_id, limit=limit)
AttributeError: 'ChatChannel' object has no attribute '_channel_id'

The above exception was the direct cause of the following exception:

Traceback (most recent call last):
  File "/home/minecraft/multicraft/servers/server223117/.local/lib/python3.9/site-packages/guilded/ext/commands/bot.py", line 452, in invoke
    await ctx.command.invoke(ctx)
  File "/home/minecraft/multicraft/servers/server223117/.local/lib/python3.9/site-packages/guilded/ext/commands/core.py", line 619, in invoke
    await injected(*ctx.args, **ctx.kwargs)
  File "/home/minecraft/multicraft/servers/server223117/.local/lib/python3.9/site-packages/guilded/ext/commands/core.py", line 92, in wrapped
    raise CommandInvokeError(exc) from exc
guilded.ext.commands.errors.CommandInvokeError: Command raised an exception: AttributeError: 'ChatChannel' object has no attribute '_channel_id'
