Defaulting to user installation because normal site-packages is not writeable
Requirement already satisfied: discord.py in ./.local/lib/python3.9/site-packages (1.7.3)
Requirement already satisfied: aiohttp<3.8.0,>=3.6.0 in ./.local/lib/python3.9/site-packages (from discord.py) (3.7.4.post0)
Requirement already satisfied: yarl<2.0,>=1.0 in ./.local/lib/python3.9/site-packages (from aiohttp<3.8.0,>=3.6.0->discord.py) (1.6.3)
Requirement already satisfied: async-timeout<4.0,>=3.0 in ./.local/lib/python3.9/site-packages (from aiohttp<3.8.0,>=3.6.0->discord.py) (3.0.1)
Requirement already satisfied: typing-extensions>=3.6.5 in ./.local/lib/python3.9/site-packages (from aiohttp<3.8.0,>=3.6.0->discord.py) (3.10.0.2)
Requirement already satisfied: chardet<5.0,>=2.0 in ./.local/lib/python3.9/site-packages (from aiohttp<3.8.0,>=3.6.0->discord.py) (4.0.0)
Requirement already satisfied: attrs>=17.3.0 in ./.local/lib/python3.9/site-packages (from aiohttp<3.8.0,>=3.6.0->discord.py) (21.2.0)
Requirement already satisfied: multidict<7.0,>=4.5 in ./.local/lib/python3.9/site-packages (from aiohttp<3.8.0,>=3.6.0->discord.py) (5.2.0)
Requirement already satisfied: idna>=2.0 in /usr/lib/python3/dist-packages (from yarl<2.0,>=1.0->aiohttp<3.8.0,>=3.6.0->discord.py) (2.6)
WARNING: You are using pip version 21.2.4; however, version 21.3 is available.
You should consider upgrading via the '/usr/bin/python3.7 -m pip install --upgrade pip' command.
Logged in as altereal.bot (ID: 4WP0JYEd)
------
Task exception was never retrieved
future: <Task finished name='Task-1' coro=<Client.start() done, defined at /home/minecraft/multicraft/servers/server223117/.local/lib/python3.9/site-packages/guilded/client.py:319> exception=ClientConnectorError(ConnectionKey(host='api.guilded.gg', port=443, is_ssl=True, ssl=None, proxy=None, proxy_auth=None, proxy_headers_hash=None), gaierror(-3, 'Temporary failure in name resolution'))>
Traceback (most recent call last):
  File "/home/minecraft/multicraft/servers/server223117/.local/lib/python3.9/site-packages/aiohttp/connector.py", line 999, in _create_direct_connection
    hosts = await asyncio.shield(host_resolved)
  File "/home/minecraft/multicraft/servers/server223117/.local/lib/python3.9/site-packages/aiohttp/connector.py", line 865, in _resolve_host
    addrs = await self._resolver.resolve(host, port, family=self._family)
  File "/home/minecraft/multicraft/servers/server223117/.local/lib/python3.9/site-packages/aiohttp/resolver.py", line 31, in resolve
    infos = await self._loop.getaddrinfo(
  File "/usr/lib/python3.9/asyncio/base_events.py", line 856, in getaddrinfo
    return await self.run_in_executor(
  File "/usr/lib/python3.9/concurrent/futures/thread.py", line 52, in run
    result = self.fn(*self.args, **self.kwargs)
  File "/usr/lib/python3.9/socket.py", line 954, in getaddrinfo
    for res in _socket.getaddrinfo(host, port, family, type, proto, flags):
socket.gaierror: [Errno -3] Temporary failure in name resolution

The above exception was the direct cause of the following exception:

Traceback (most recent call last):
  File "/home/minecraft/multicraft/servers/server223117/.local/lib/python3.9/site-packages/guilded/client.py", line 325, in start
    await self.connect()
  File "/home/minecraft/multicraft/servers/server223117/.local/lib/python3.9/site-packages/guilded/client.py", line 446, in connect
    await asyncio.gather(
  File "/home/minecraft/multicraft/servers/server223117/.local/lib/python3.9/site-packages/guilded/client.py", line 436, in listen_socks
    ws = await asyncio.wait_for(build, timeout=60)
  File "/usr/lib/python3.9/asyncio/tasks.py", line 481, in wait_for
    return fut.result()
  File "/home/minecraft/multicraft/servers/server223117/.local/lib/python3.9/site-packages/guilded/gateway.py", line 109, in build
    socket = await client.http.ws_connect(**gateway_args)
  File "/home/minecraft/multicraft/servers/server223117/.local/lib/python3.9/site-packages/guilded/http.py", line 274, in ws_connect
    return await self.session.ws_connect(
  File "/home/minecraft/multicraft/servers/server223117/.local/lib/python3.9/site-packages/aiohttp/client.py", line 754, in _ws_connect
    resp = await self.request(
  File "/home/minecraft/multicraft/servers/server223117/.local/lib/python3.9/site-packages/aiohttp/client.py", line 520, in _request
    conn = await self._connector.connect(
  File "/home/minecraft/multicraft/servers/server223117/.local/lib/python3.9/site-packages/aiohttp/connector.py", line 535, in connect
    proto = await self._create_connection(req, traces, timeout)
  File "/home/minecraft/multicraft/servers/server223117/.local/lib/python3.9/site-packages/aiohttp/connector.py", line 892, in _create_connection
    _, proto = await self._create_direct_connection(req, traces, timeout)
  File "/home/minecraft/multicraft/servers/server223117/.local/lib/python3.9/site-packages/aiohttp/connector.py", line 1011, in _create_direct_connection
    raise ClientConnectorError(req.connection_key, exc) from exc
aiohttp.client_exceptions.ClientConnectorError: Cannot connect to host api.guilded.gg:443 ssl:default [Temporary failure in name resolution]
