Defaulting to user installation because normal site-packages is not writeable
Requirement already satisfied: discord.py in ./.local/lib/python3.9/site-packages (1.7.3)
Requirement already satisfied: aiohttp<3.8.0,>=3.6.0 in ./.local/lib/python3.9/site-packages (from discord.py) (3.7.4.post0)
Requirement already satisfied: multidict<7.0,>=4.5 in ./.local/lib/python3.9/site-packages (from aiohttp<3.8.0,>=3.6.0->discord.py) (5.2.0)
Requirement already satisfied: attrs>=17.3.0 in ./.local/lib/python3.9/site-packages (from aiohttp<3.8.0,>=3.6.0->discord.py) (21.2.0)
Requirement already satisfied: chardet<5.0,>=2.0 in ./.local/lib/python3.9/site-packages (from aiohttp<3.8.0,>=3.6.0->discord.py) (4.0.0)
Requirement already satisfied: typing-extensions>=3.6.5 in ./.local/lib/python3.9/site-packages (from aiohttp<3.8.0,>=3.6.0->discord.py) (3.10.0.2)
Requirement already satisfied: yarl<2.0,>=1.0 in ./.local/lib/python3.9/site-packages (from aiohttp<3.8.0,>=3.6.0->discord.py) (1.6.3)
Requirement already satisfied: async-timeout<4.0,>=3.0 in ./.local/lib/python3.9/site-packages (from aiohttp<3.8.0,>=3.6.0->discord.py) (3.0.1)
Requirement already satisfied: idna>=2.0 in /usr/lib/python3/dist-packages (from yarl<2.0,>=1.0->aiohttp<3.8.0,>=3.6.0->discord.py) (2.6)
Logged in as Phedre (ID: dNM6kvk4)
------
Ignoring exception in command None:
guilded.ext.commands.errors.CommandNotFound: Command "bot" is not found
Ignoring exception in command None:
guilded.ext.commands.errors.CommandNotFound: Command "d6" is not found
Ignoring exception in command None:
guilded.ext.commands.errors.CommandNotFound: Command "add(3,4)" is not found
Ignoring exception in command None:
guilded.ext.commands.errors.CommandNotFound: Command "bot" is not found
Ignoring exception in command None:
guilded.ext.commands.errors.CommandNotFound: Command "_bot" is not found
Ignoring exception in command None:
guilded.ext.commands.errors.CommandNotFound: Command "roll(3d6)" is not found
Ignoring exception in command None:
guilded.ext.commands.errors.CommandNotFound: Command "roll('3d6')" is not found
Task exception was never retrieved
future: <Task finished name='Task-1' coro=<Client.start() done, defined at /home/minecraft/multicraft/servers/server223117/.local/lib/python3.9/site-packages/guilded/client.py:319> exception=GuildedException(TypeError("'NoneType' object is not iterable"))>
Traceback (most recent call last):
  File "/home/minecraft/multicraft/servers/server223117/.local/lib/python3.9/site-packages/guilded/gateway.py", line 171, in received_event
    await event
  File "/home/minecraft/multicraft/servers/server223117/.local/lib/python3.9/site-packages/guilded/gateway.py", line 321, in ChatMessageUpdated
    after = Message(state=self.client.http, channel=before.channel, author=before.author, data=data)
  File "/home/minecraft/multicraft/servers/server223117/.local/lib/python3.9/site-packages/guilded/message.py", line 278, in __init__
    for message_id in self.replied_to_ids:
TypeError: 'NoneType' object is not iterable

The above exception was the direct cause of the following exception:

Traceback (most recent call last):
  File "/home/minecraft/multicraft/servers/server223117/.local/lib/python3.9/site-packages/guilded/client.py", line 325, in start
    await self.connect()
  File "/home/minecraft/multicraft/servers/server223117/.local/lib/python3.9/site-packages/guilded/client.py", line 446, in connect
    await asyncio.gather(
  File "/home/minecraft/multicraft/servers/server223117/.local/lib/python3.9/site-packages/guilded/client.py", line 420, in listen_socks
    await ws.poll_event()
  File "/home/minecraft/multicraft/servers/server223117/.local/lib/python3.9/site-packages/guilded/gateway.py", line 184, in poll_event
    await self.received_event(msg.data)
  File "/home/minecraft/multicraft/servers/server223117/.local/lib/python3.9/site-packages/guilded/gateway.py", line 179, in received_event
    raise exc from e
guilded.errors.GuildedException: 'NoneType' object is not iterable
