Defaulting to user installation because normal site-packages is not writeable
Requirement already satisfied: discord.py in ./.local/lib/python3.9/site-packages (1.7.3)
Requirement already satisfied: aiohttp<3.8.0,>=3.6.0 in ./.local/lib/python3.9/site-packages (from discord.py) (3.7.4.post0)
Requirement already satisfied: yarl<2.0,>=1.0 in ./.local/lib/python3.9/site-packages (from aiohttp<3.8.0,>=3.6.0->discord.py) (1.6.3)
Requirement already satisfied: chardet<5.0,>=2.0 in ./.local/lib/python3.9/site-packages (from aiohttp<3.8.0,>=3.6.0->discord.py) (4.0.0)
Requirement already satisfied: multidict<7.0,>=4.5 in ./.local/lib/python3.9/site-packages (from aiohttp<3.8.0,>=3.6.0->discord.py) (5.2.0)
Requirement already satisfied: attrs>=17.3.0 in ./.local/lib/python3.9/site-packages (from aiohttp<3.8.0,>=3.6.0->discord.py) (21.2.0)
Requirement already satisfied: async-timeout<4.0,>=3.0 in ./.local/lib/python3.9/site-packages (from aiohttp<3.8.0,>=3.6.0->discord.py) (3.0.1)
Requirement already satisfied: typing-extensions>=3.6.5 in ./.local/lib/python3.9/site-packages (from aiohttp<3.8.0,>=3.6.0->discord.py) (3.10.0.2)
Requirement already satisfied: idna>=2.0 in /usr/lib/python3/dist-packages (from yarl<2.0,>=1.0->aiohttp<3.8.0,>=3.6.0->discord.py) (2.6)
WARNING: You are using pip version 21.2.4; however, version 21.3.1 is available.
You should consider upgrading via the '/usr/bin/python3.7 -m pip install --upgrade pip' command.
Logged in as altereal.bot (ID: 4WP0JYEd)
------
Python modules reloaded
Ignoring exception in command reload:
Traceback (most recent call last):
  File "/home/minecraft/multicraft/servers/server223117/.local/lib/python3.9/site-packages/guilded/ext/commands/core.py", line 83, in wrapped
    ret = await coro(*args, **kwargs)
  File "/home/minecraft/multicraft/servers/server223117/guilded_altereal.py", line 327, in reload
    await ctx.send("Python modules reloaded")
  File "/home/minecraft/multicraft/servers/server223117/.local/lib/python3.9/site-packages/guilded/abc.py", line 187, in send
    response_coro, payload = self._state.send_message(self._channel_id, content, message_payload, share_urls=share_urls)
  File "/home/minecraft/multicraft/servers/server223117/.local/lib/python3.9/site-packages/guilded/http.py", line 416, in send_message
    'messageId': utils.new_uuid(),
  File "/home/minecraft/multicraft/servers/server223117/.local/lib/python3.9/site-packages/guilded/utils.py", line 106, in new_uuid
    return str(uuid1())
  File "/usr/lib/python3.9/uuid.py", line 692, in uuid1
    import random
  File "/usr/lib/python3.9/random.py", line 48, in <module>
    from warnings import warn as _warn
  File "/usr/lib/python3.9/warnings.py", line 538, in <module>
    _processoptions(sys.warnoptions)
AttributeError: module 'sys' has no attribute 'warnoptions'

The above exception was the direct cause of the following exception:

Traceback (most recent call last):
  File "/home/minecraft/multicraft/servers/server223117/.local/lib/python3.9/site-packages/guilded/ext/commands/bot.py", line 452, in invoke
    await ctx.command.invoke(ctx)
  File "/home/minecraft/multicraft/servers/server223117/.local/lib/python3.9/site-packages/guilded/ext/commands/core.py", line 619, in invoke
    await injected(*ctx.args, **ctx.kwargs)
  File "/home/minecraft/multicraft/servers/server223117/.local/lib/python3.9/site-packages/guilded/ext/commands/core.py", line 92, in wrapped
    raise CommandInvokeError(exc) from exc
guilded.ext.commands.errors.CommandInvokeError: Command raised an exception: AttributeError: module 'sys' has no attribute 'warnoptions'
